{"variants":[{"traits":[{"interfaceLanguage":"swift"}],"paths":["\/documentation\/_pythonstring\/pyexception\/baseexception(_:)"]}],"metadata":{"fragments":[{"kind":"keyword","text":"case"},{"text":" ","kind":"text"},{"text":"baseException","kind":"identifier"},{"kind":"text","text":"("},{"preciseIdentifier":"s:SS","text":"String","kind":"typeIdentifier"},{"text":")","kind":"text"}],"modules":[{"name":"_PythonString"}],"roleHeading":"Case","externalID":"s:13_PythonString11PyExceptionO04baseD0yACSScACmF","title":"PyException.baseException(_:)","role":"symbol","symbolKind":"case"},"kind":"symbol","primaryContentSections":[{"kind":"declarations","declarations":[{"platforms":["macOS"],"languages":["swift"],"tokens":[{"text":"case","kind":"keyword"},{"text":" ","kind":"text"},{"text":"baseException","kind":"identifier"},{"text":"(","kind":"text"},{"preciseIdentifier":"s:SS","text":"String","kind":"typeIdentifier"},{"kind":"text","text":")"}]}]}],"sections":[],"identifier":{"interfaceLanguage":"swift","url":"doc:\/\/com.swallow.documentation._PythonString\/documentation\/_PythonString\/PyException\/baseException(_:)"},"hierarchy":{"paths":[["doc:\/\/com.swallow.documentation._PythonString\/documentation\/_PythonString","doc:\/\/com.swallow.documentation._PythonString\/documentation\/_PythonString\/PyException"]]},"schemaVersion":{"major":0,"minor":3,"patch":0},"references":{"doc://com.swallow.documentation._PythonString/documentation/_PythonString/PyException/baseException(_:)":{"identifier":"doc:\/\/com.swallow.documentation._PythonString\/documentation\/_PythonString\/PyException\/baseException(_:)","title":"PyException.baseException(_:)","kind":"symbol","fragments":[{"text":"case","kind":"keyword"},{"text":" ","kind":"text"},{"text":"baseException","kind":"identifier"},{"text":"(","kind":"text"},{"kind":"typeIdentifier","preciseIdentifier":"s:SS","text":"String"},{"text":")","kind":"text"}],"url":"\/documentation\/_pythonstring\/pyexception\/baseexception(_:)","type":"topic","abstract":[],"role":"symbol"},"doc://com.swallow.documentation._PythonString/documentation/_PythonString/PyException":{"title":"PyException","navigatorTitle":[{"text":"PyException","kind":"identifier"}],"abstract":[],"type":"topic","url":"\/documentation\/_pythonstring\/pyexception","kind":"symbol","identifier":"doc:\/\/com.swallow.documentation._PythonString\/documentation\/_PythonString\/PyException","role":"symbol","fragments":[{"text":"enum","kind":"keyword"},{"kind":"text","text":" "},{"text":"PyException","kind":"identifier"}]},"doc://com.swallow.documentation._PythonString/documentation/_PythonString":{"identifier":"doc:\/\/com.swallow.documentation._PythonString\/documentation\/_PythonString","role":"collection","kind":"symbol","abstract":[],"type":"topic","title":"_PythonString","url":"\/documentation\/_pythonstring"}}}