{"identifier":{"url":"doc:\/\/com.swallow.documentation._PythonString\/documentation\/_PythonString\/PyException\/systemError(_:)","interfaceLanguage":"swift"},"schemaVersion":{"patch":0,"minor":3,"major":0},"kind":"symbol","sections":[],"hierarchy":{"paths":[["doc:\/\/com.swallow.documentation._PythonString\/documentation\/_PythonString","doc:\/\/com.swallow.documentation._PythonString\/documentation\/_PythonString\/PyException"]]},"variants":[{"traits":[{"interfaceLanguage":"swift"}],"paths":["\/documentation\/_pythonstring\/pyexception\/systemerror(_:)"]}],"metadata":{"title":"PyException.systemError(_:)","modules":[{"name":"_PythonString"}],"fragments":[{"kind":"keyword","text":"case"},{"text":" ","kind":"text"},{"kind":"identifier","text":"systemError"},{"kind":"text","text":"("},{"text":"String","kind":"typeIdentifier","preciseIdentifier":"s:SS"},{"kind":"text","text":")"}],"roleHeading":"Case","role":"symbol","externalID":"s:13_PythonString11PyExceptionO11systemErroryACSScACmF","symbolKind":"case"},"primaryContentSections":[{"kind":"declarations","declarations":[{"languages":["swift"],"platforms":["macOS"],"tokens":[{"text":"case","kind":"keyword"},{"text":" ","kind":"text"},{"text":"systemError","kind":"identifier"},{"kind":"text","text":"("},{"preciseIdentifier":"s:SS","kind":"typeIdentifier","text":"String"},{"kind":"text","text":")"}]}]}],"references":{"doc://com.swallow.documentation._PythonString/documentation/_PythonString":{"abstract":[],"role":"collection","title":"_PythonString","identifier":"doc:\/\/com.swallow.documentation._PythonString\/documentation\/_PythonString","url":"\/documentation\/_pythonstring","type":"topic","kind":"symbol"},"doc://com.swallow.documentation._PythonString/documentation/_PythonString/PyException/systemError(_:)":{"role":"symbol","fragments":[{"kind":"keyword","text":"case"},{"text":" ","kind":"text"},{"kind":"identifier","text":"systemError"},{"text":"(","kind":"text"},{"kind":"typeIdentifier","text":"String","preciseIdentifier":"s:SS"},{"text":")","kind":"text"}],"identifier":"doc:\/\/com.swallow.documentation._PythonString\/documentation\/_PythonString\/PyException\/systemError(_:)","title":"PyException.systemError(_:)","abstract":[],"url":"\/documentation\/_pythonstring\/pyexception\/systemerror(_:)","kind":"symbol","type":"topic"},"doc://com.swallow.documentation._PythonString/documentation/_PythonString/PyException":{"title":"PyException","navigatorTitle":[{"text":"PyException","kind":"identifier"}],"abstract":[],"type":"topic","url":"\/documentation\/_pythonstring\/pyexception","kind":"symbol","identifier":"doc:\/\/com.swallow.documentation._PythonString\/documentation\/_PythonString\/PyException","role":"symbol","fragments":[{"text":"enum","kind":"keyword"},{"kind":"text","text":" "},{"text":"PyException","kind":"identifier"}]}}}