{"hierarchy":{"paths":[["doc:\/\/com.swallow.documentation.FoundationX\/documentation\/FoundationX","doc:\/\/com.swallow.documentation.FoundationX\/documentation\/FoundationX\/URLError"]]},"sections":[],"kind":"symbol","abstract":[{"type":"text","text":"The reason why the network is unavailable when the task failed due to unsatisfiable network constraints."}],"primaryContentSections":[{"kind":"declarations","declarations":[{"tokens":[{"kind":"keyword","text":"var"},{"text":" ","kind":"text"},{"kind":"identifier","text":"networkUnavailableReason"},{"text":": ","kind":"text"},{"identifier":"doc:\/\/com.swallow.documentation.FoundationX\/documentation\/FoundationX\/URLError","preciseIdentifier":"s:10Foundation8URLErrorV","text":"URLError","kind":"typeIdentifier"},{"text":".","kind":"text"},{"kind":"typeIdentifier","preciseIdentifier":"s:10Foundation8URLErrorV24NetworkUnavailableReasonO","text":"NetworkUnavailableReason","identifier":"doc:\/\/com.swallow.documentation.FoundationX\/documentation\/FoundationX\/URLError\/NetworkUnavailableReason-swift.enum"},{"kind":"text","text":"? { "},{"text":"get","kind":"keyword"},{"text":" }","kind":"text"}],"platforms":["macOS"],"languages":["swift"]}]}],"identifier":{"interfaceLanguage":"swift","url":"doc:\/\/com.swallow.documentation.FoundationX\/documentation\/FoundationX\/URLError\/networkUnavailableReason-swift.property"},"metadata":{"symbolKind":"property","title":"networkUnavailableReason","roleHeading":"Instance Property","platforms":[{"deprecated":false,"unavailable":false,"introducedAt":"13.0","name":"iOS","beta":false},{"name":"macOS","beta":false,"deprecated":false,"introducedAt":"10.15","unavailable":false},{"introducedAt":"13.0","deprecated":false,"unavailable":false,"beta":false,"name":"tvOS"},{"name":"watchOS","deprecated":false,"unavailable":false,"introducedAt":"6.0","beta":false}],"role":"symbol","externalID":"s:10Foundation8URLErrorV24networkUnavailableReasonAC07NetworkdE0OSgvp","fragments":[{"text":"var","kind":"keyword"},{"text":" ","kind":"text"},{"text":"networkUnavailableReason","kind":"identifier"},{"text":": ","kind":"text"},{"kind":"typeIdentifier","text":"URLError","preciseIdentifier":"s:10Foundation8URLErrorV"},{"text":".","kind":"text"},{"preciseIdentifier":"s:10Foundation8URLErrorV24NetworkUnavailableReasonO","text":"NetworkUnavailableReason","kind":"typeIdentifier"},{"text":"?","kind":"text"}],"modules":[{"name":"FoundationX","relatedModules":["Foundation"]}],"extendedModule":"Foundation"},"schemaVersion":{"patch":0,"minor":3,"major":0},"variants":[{"traits":[{"interfaceLanguage":"swift"}],"paths":["\/documentation\/foundationx\/urlerror\/networkunavailablereason-swift.property"]}],"references":{"doc://com.swallow.documentation.FoundationX/documentation/FoundationX/URLError":{"title":"URLError","role":"symbol","url":"\/documentation\/foundationx\/urlerror","type":"topic","kind":"symbol","identifier":"doc:\/\/com.swallow.documentation.FoundationX\/documentation\/FoundationX\/URLError","abstract":[{"text":"Describes errors in the URL error domain.","type":"text"}],"navigatorTitle":[{"text":"URLError","kind":"identifier"}],"fragments":[{"text":"struct","kind":"keyword"},{"kind":"text","text":" "},{"kind":"identifier","text":"URLError"}]},"doc://com.swallow.documentation.FoundationX/documentation/FoundationX/URLError/networkUnavailableReason-swift.property":{"title":"networkUnavailableReason","url":"\/documentation\/foundationx\/urlerror\/networkunavailablereason-swift.property","kind":"symbol","type":"topic","role":"symbol","fragments":[{"text":"var","kind":"keyword"},{"text":" ","kind":"text"},{"text":"networkUnavailableReason","kind":"identifier"},{"text":": ","kind":"text"},{"kind":"typeIdentifier","text":"URLError","preciseIdentifier":"s:10Foundation8URLErrorV"},{"text":".","kind":"text"},{"preciseIdentifier":"s:10Foundation8URLErrorV24NetworkUnavailableReasonO","text":"NetworkUnavailableReason","kind":"typeIdentifier"},{"text":"?","kind":"text"}],"abstract":[{"type":"text","text":"The reason why the network is unavailable when the task failed due to unsatisfiable network constraints."}],"identifier":"doc:\/\/com.swallow.documentation.FoundationX\/documentation\/FoundationX\/URLError\/networkUnavailableReason-swift.property"},"doc://com.swallow.documentation.FoundationX/documentation/FoundationX":{"abstract":[],"kind":"symbol","title":"FoundationX","identifier":"doc:\/\/com.swallow.documentation.FoundationX\/documentation\/FoundationX","url":"\/documentation\/foundationx","role":"collection","type":"topic"},"doc://com.swallow.documentation.FoundationX/documentation/FoundationX/URLError/NetworkUnavailableReason-swift.enum":{"type":"topic","fragments":[{"text":"enum","kind":"keyword"},{"kind":"text","text":" "},{"text":"NetworkUnavailableReason","kind":"identifier"}],"url":"\/documentation\/foundationx\/urlerror\/networkunavailablereason-swift.enum","kind":"symbol","identifier":"doc:\/\/com.swallow.documentation.FoundationX\/documentation\/FoundationX\/URLError\/NetworkUnavailableReason-swift.enum","role":"symbol","title":"URLError.NetworkUnavailableReason","abstract":[{"text":"Reasons used by URLError to indicate that a URLSessionTask failed because of unsatisfiable network constraints.","type":"text"}],"navigatorTitle":[{"kind":"identifier","text":"NetworkUnavailableReason"}]}}}